Workbook
Name Slicer_Driver_Code: #N/A
Name Slicer_Tyre_Compound: #N/A

Sheet RaceData
A1: Driver_Code | B1: Driver_Name | C1: Team | D1: Car_Number | E1: Lap | F1: Tyre_Compound | G1: Lap_On_Tyre | H1: Lap_Time_s | I1: S1_Time_s | J1: S2_Time_s | K1: S3_Time_s | L1: Is_Pit_Lap | M1: Pit_Stop_Duration_s | N1: Gap_To_Leader_s | O1: Sector_Check | R1: Lap
A2: VER | B2: Max Verstappen | C2: Red Bull | D2: 1 | E2: 1 | F2: Soft | G2: 1 | H2: 97.846 | I2: 30.371 | J2: 40.201 | K2: 27.274 | L2: NO | N2: 0 | O2: =IF(ABS((I2+J2+K2)-H2)<0.01, "OK", "MISMATCH" ) -> OK | R2: 1
A3: HAM | B3: Lewis Hamilton | C3: Mercedes | D3: 44 | E3: 1 | F3: Medium | G3: 1 | H3: 99.305 | I3: 30.868 | J3: 40.572 | K3: 27.864 | L3: NO | N3: 0 | O3: =IF(ABS((I3+J3+K3)-H3)<0.01, "OK", "MISMATCH" ) -> OK | R3: 2
A4: ALO | B4: Fernando Alonso | C4: Aston Martin | D4: 14 | E4: 1 | F4: Soft | G4: 1 | H4: 97.816 | I4: 30.419 | J4: 40.075 | K4: 27.322 | L4: NO | N4: 0 | O4: =IF(ABS((I4+J4+K4)-H4)<0.01, "OK", "MISMATCH" ) -> OK | R4: 3
A5: LEC | B5: Charles Leclerc | C5: Ferrari | D5: 16 | E5: 1 | F5: Soft | G5: 1 | H5: 97.482 | I5: 30.166 | J5: 40.019 | K5: 27.298 | L5: NO | N5: 0 | O5: =IF(ABS((I5+J5+K5)-H5)<0.01, "OK", "MISMATCH" ) -> OK | R5: =R4 + 1 -> 4
A6: NOR | B6: Lando Norris | C6: McLaren | D6: 4 | E6: 1 | F6: Medium | G6: 1 | H6: 99.749 | I6: 30.784 | J6: 40.864 | K6: 28.101 | L6: NO | N6: 0 | O6: =IF(ABS((I6+J6+K6)-H6)<0.01, "OK", "MISMATCH" ) -> OK | R6: =R5 + 1 -> 5
A7: VER | B7: Max Verstappen | C7: Red Bull | D7: 1 | E7: 2 | F7: Soft | G7: 2 | H7: 92.878 | I7: 28.784 | J7: 38.035 | K7: 26.059 | L7: NO | N7: 0 | O7: =IF(ABS((I7+J7+K7)-H7)<0.01, "OK", "MISMATCH" ) -> OK | R7: =R6 + 1 -> 6
A8: HAM | B8: Lewis Hamilton | C8: Mercedes | D8: 44 | E8: 2 | F8: Medium | G8: 2 | H8: 94.841 | I8: 29.427 | J8: 38.898 | K8: 26.516 | L8: NO | N8: 3.421 | O8: =IF(ABS((I8+J8+K8)-H8)<0.01, "OK", "MISMATCH" ) -> OK | R8: =R7 + 1 -> 7
A9: ALO | B9: Fernando Alonso | C9: Aston Martin | D9: 14 | E9: 2 | F9: Soft | G9: 2 | H9: 93.538 | I9: 29.021 | J9: 38.473 | K9: 26.045 | L9: NO | N9: 0.63 | O9: =IF(ABS((I9+J9+K9)-H9)<0.01, "OK", "MISMATCH" ) -> OK | R9: =R8 + 1 -> 8
A10: LEC | B10: Charles Leclerc | C10: Ferrari | D10: 16 | E10: 2 | F10: Soft | G10: 2 | H10: 94.069 | I10: 29.207 | J10: 38.562 | K10: 26.3 | L10: NO | N10: 0.827 | O10: =IF(ABS((I10+J10+K10)-H10)<0.01, "OK", "MISMATCH" ) -> OK | R10: =R9 + 1 -> 9
A11: NOR | B11: Lando Norris | C11: McLaren | D11: 4 | E11: 2 | F11: Medium | G11: 2 | H11: 95.34 | I11: 29.587 | J11: 39.132 | K11: 26.621 | L11: NO | N11: 4.365 | O11: =IF(ABS((I11+J11+K11)-H11)<0.01, "OK", "MISMATCH" ) -> OK | R11: =R10 + 1 -> 10
A12: VER | B12: Max Verstappen | C12: Red Bull | D12: 1 | E12: 3 | F12: Soft | G12: 3 | H12: 92.975 | I12: 28.896 | J12: 38.057 | K12: 26.022 | L12: NO | N12: 0 | O12: =IF(ABS((I12+J12+K12)-H12)<0.01, "OK", "MISMATCH" ) -> OK | R12: =R11 + 1 -> 11
A13: HAM | B13: Lewis Hamilton | C13: Mercedes | D13: 44 | E13: 3 | F13: Medium | G13: 3 | H13: 94.82 | I13: 29.291 | J13: 38.927 | K13: 26.601 | L13: NO | N13: 5.267 | O13: =IF(ABS((I13+J13+K13)-H13)<0.01, "OK", "MISMATCH" ) -> OK | R13: =R12 + 1 -> 12
A14: ALO | B14: Fernando Alonso | C14: Aston Martin | D14: 14 | E14: 3 | F14: Soft | G14: 3 | H14: 93.89 | I14: 29.128 | J14: 38.576 | K14: 26.186 | L14: NO | N14: 1.545 | O14: =IF(ABS((I14+J14+K14)-H14)<0.01, "OK", "MISMATCH" ) -> OK | R14: =R13 + 1 -> 13
A15: LEC | B15: Charles Leclerc | C15: Ferrari | D15: 16 | E15: 3 | F15: Soft | G15: 3 | H15: 94.034 | I15: 29.253 | J15: 38.647 | K15: 26.134 | L15: NO | N15: 1.886 | O15: =IF(ABS((I15+J15+K15)-H15)<0.01, "OK", "MISMATCH" ) -> OK | R15: =R14 + 1 -> 14
A16: NOR | B16: Lando Norris | C16: McLaren | D16: 4 | E16: 3 | F16: Medium | G16: 3 | H16: 95.399 | I16: 29.486 | J16: 39.237 | K16: 26.675 | L16: NO | N16: 6.789 | O16: =IF(ABS((I16+J16+K16)-H16)<0.01, "OK", "MISMATCH" ) -> OK | R16: =R15 + 1 -> 15
... A58: HAM | B58: Lewis Hamilton | C58: Mercedes | D58: 44 | E58: 12 | F58: Medium | G58: 12 | H58: 103.759 | I58: 32.039 | J58: 42.194 | K58: 29.526 | L58: NO | N58: 22.497 | O58: =IF(ABS((I58+J58+K58)-H58)<0.01, "OK", "MISMATCH" ) -> OK | R58: =R57 + 1 -> 57
A59: ALO | B59: Fernando Alonso | C59: Aston Martin | D59: 14 | E59: 12 | F59: Soft | G59: 12 | H59: 102.967 | I59: 31.842 | J59: 41.979 | K59: 29.146 | L59: NO | N59: 9.413 | O59: =IF(ABS((I59+J59+K59)-H59)<0.01, "OK", "MISMATCH" ) -> OK
A60: LEC | B60: Charles Leclerc | C60: Ferrari | D60: 16 | E60: 12 | F60: Soft | G60: 12 | H60: 103.213 | I60: 31.714 | J60: 41.873 | K60: 29.626 | L60: NO | N60: 10.261 | O60: =IF(ABS((I60+J60+K60)-H60)<0.01, "OK", "MISMATCH" ) -> OK
A61: NOR | B61: Lando Norris | C61: McLaren | D61: 4 | E61: 12 | F61: Medium | G61: 12 | H61: 104.639 | I61: 32.215 | J61: 42.445 | K61: 29.979 | L61: NO | N61: 27.343 | O61: =IF(ABS((I61+J61+K61)-H61)<0.01, "OK", "MISMATCH" ) -> OK
A62: VER | B62: Max Verstappen | C62: Red Bull | D62: 1 | E62: 13 | F62: Soft | G62: 13 | H62: 102.221 | I62: 31.454 | J62: 41.534 | K62: 29.232 | L62: NO | N62: 0 | O62: =IF(ABS((I62+J62+K62)-H62)<0.01, "OK", "MISMATCH" ) -> OK
A63: HAM | B63: Lewis Hamilton | C63: Mercedes | D63: 44 | E63: 13 | F63: Medium | G63: 13 | H63: 103.895 | I63: 32.129 | J63: 42.448 | K63: 29.318 | L63: NO | N63: 24.171 | O63: =IF(ABS((I63+J63+K63)-H63)<0.01, "OK", "MISMATCH" ) -> OK
A64: ALO | B64: Fernando Alonso | C64: Aston Martin | D64: 14 | E64: 13 | F64: Soft | G64: 13 | H64: 103.134 | I64: 31.733 | J64: 41.986 | K64: 29.415 | L64: NO | N64: 10.326 | O64: =IF(ABS((I64+J64+K64)-H64)<0.01, "OK", "MISMATCH" ) -> OK
A65: LEC | B65: Charles Leclerc | C65: Ferrari | D65: 16 | E65: 13 | F65: Soft | G65: 13 | H65: 103.176 | I65: 31.835 | J65: 41.967 | K65: 29.375 | L65: NO | N65: 11.216 | O65: =IF(ABS((I65+J65+K65)-H65)<0.01, "OK", "MISMATCH" ) -> OK
A66: NOR | B66: Lando Norris | C66: McLaren | D66: 4 | E66: 13 | F66: Medium | G66: 13 | H66: 104.741 | I66: 32.203 | J66: 42.588 | K66: 29.949 | L66: NO | N66: 29.863 | O66: =IF(ABS((I66+J66+K66)-H66)<0.01, "OK", "MISMATCH" ) -> OK
A67: VER | B67: Max Verstappen | C67: Red Bull | D67: 1 | E67: 14 | F67: Soft | G67: 14 | H67: 93.814 | I67: 28.899 | J67: 38.162 | K67: 26.753 | L67: NO | N67: 0 | O67: =IF(ABS((I67+J67+K67)-H67)<0.01, "OK", "MISMATCH" ) -> OK
A68: HAM | B68: Lewis Hamilton | C68: Mercedes | D68: 44 | E68: 14 | F68: Medium | G68: 14 | H68: 95.664 | I68: 29.435 | J68: 38.783 | K68: 27.446 | L68: NO | N68: 26.021 | O68: =IF(ABS((I68+J68+K68)-H68)<0.01, "OK", "MISMATCH" ) -> OK
A69: ALO | B69: Fernando Alonso | C69: Aston Martin | D69: 14 | E69: 14 | F69: Soft | G69: 14 | H69: 94.901 | I69: 29.247 | J69: 38.612 | K69: 27.042 | L69: NO | N69: 11.413 | O69: =IF(ABS((I69+J69+K69)-H69)<0.01, "OK", "MISMATCH" ) -> OK
A70: LEC | B70: Charles Leclerc | C70: Ferrari | D70: 16 | E70: 14 | F70: Soft | G70: 14 | H70: 94.811 | I70: 29.045 | J70: 38.508 | K70: 27.257 | L70: NO | N70: 12.213 | O70: =IF(ABS((I70+J70+K70)-H70)<0.01, "OK", "MISMATCH" ) -> OK
... A78: HAM | B78: Lewis Hamilton | C78: Mercedes | D78: 44 | E78: 16 | F78: Medium | G78: 16 | H78: 95.924 | I78: 29.39 | J78: 38.793 | K78: 27.741 | L78: NO | N78: 29.067 | O78: =IF(ABS((I78+J78+K78)-H78)<0.01, "OK", "MISMATCH" ) -> OK
A79: ALO | B79: Fernando Alonso | C79: Aston Martin | D79: 14 | E79: 16 | F79: Soft | G79: 16 | H79: 113.515 | I79: 29.03 | J79: 38.491 | K79: 45.994 | L79: YES | M79: 2.7 | N79: 31.464 | O79: =IF(ABS((I79+J79+K79)-H79)<0.01, "OK", "MISMATCH" ) -> OK
A80: LEC | B80: Charles Leclerc | C80: Ferrari | D80: 16 | E80: 16 | F80: Soft | G80: 16 | H80: 95.232 | I80: 29.118 | J80: 38.641 | K80: 27.472 | L80: NO | N80: 14.315 | O80: =IF(ABS((I80+J80+K80)-H80)<0.01, "OK", "MISMATCH" ) -> OK
A81: NOR | B81: Lando Norris | C81: McLaren | D81: 4 | E81: 16 | F81: Medium | G81: 16 | H81: 96.298 | I81: 29.554 | J81: 39.214 | K81: 27.529 | L81: NO | N81: 36.287 | O81: =IF(ABS((I81+J81+K81)-H81)<0.01, "OK", "MISMATCH" ) -> OK
A82: VER | B82: Max Verstappen | C82: Red Bull | D82: 1 | E82: 17 | F82: Soft | G82: 17 | H82: 94.039 | I82: 28.868 | J82: 38.224 | K82: 26.947 | L82: NO | N82: 0 | O82: =IF(ABS((I82+J82+K82)-H82)<0.01, "OK", "MISMATCH" ) -> OK
A83: HAM | B83: Lewis Hamilton | C83: Mercedes | D83: 44 | E83: 17 | F83: Medium | G83: 17 | H83: 95.938 | I83: 29.514 | J83: 39.077 | K83: 27.347 | L83: NO | N83: 30.966 | O83: =IF(ABS((I83+J83+K83)-H83)<0.01, "OK", "MISMATCH" ) -> OK
A84: ALO | B84: Fernando Alonso | C84: Aston Martin | D84: 14 | E84: 17 | F84: Hard | G84: 1 | H84: 95.752 | I84: 29.643 | J84: 39.358 | K84: 26.752 | L84: NO | N84: 33.177 | O84: =IF(ABS((I84+J84+K84)-H84)<0.01, "OK", "MISMATCH" ) -> OK
A85: LEC | B85: Charles Leclerc | C85: Ferrari | D85: 16 | E85: 17 | F85: Soft | G85: 17 | H85: 95.422 | I85: 29.198 | J85: 38.414 | K85: 27.81 | L85: NO | N85: 15.698 | O85: =IF(ABS((I85+J85+K85)-H85)<0.01, "OK", "MISMATCH" ) -> OK
A86: NOR | B86: Lando Norris | C86: McLaren | D86: 4 | E86: 17 | F86: Medium | G86: 17 | H86: 96.528 | I86: 29.557 | J86: 39.126 | K86: 27.845 | L86: NO | N86: 38.776 | O86: =IF(ABS((I86+J86+K86)-H86)<0.01, "OK", "MISMATCH" ) -> OK
A87: VER | B87: Max Verstappen | C87: Red Bull | D87: 1 | E87: 18 | F87: Soft | G87: 18 | H87: 113.928 | I87: 28.991 | J87: 38.14 | K87: 46.797 | L87: YES | M87: 2.6 | N87: 0 | O87: =IF(ABS((I87+J87+K87)-H87)<0.01, "OK", "MISMATCH" ) -> OK
A88: HAM | B88: Lewis Hamilton | C88: Mercedes | D88: 44 | E88: 18 | F88: Medium | G88: 18 | H88: 95.5 | I88: 29.313 | J88: 38.978 | K88: 27.209 | L88: NO | N88: 12.539 | O88: =IF(ABS((I88+J88+K88)-H88)<0.01, "OK", "MISMATCH" ) -> OK
...

Sheet Analysis
A1: Row Count Check | B1: =COUNTA(RaceData[Lap]) -> 285
A3: Driver | B3: Laps Completed
A4: VER | B4: =COUNTIF(RaceData[Driver_Code], A4) -> 57
A5: HAM | B5: =COUNTIF(RaceData[Driver_Code], A5) -> 57
A6: ALO | B6: =COUNTIF(RaceData[Driver_Code], A6) -> 57
A7: LEC | B7: =COUNTIF(RaceData[Driver_Code], A7) -> 57
A8: NOR | B8: =COUNTIF(RaceData[Driver_Code], A8) -> 57
A10: Driver | B10: Fastest Pit Stop (S)
A11: VER | B11: =_xlfn.MINIFS(RaceData[Pit_Stop_Duration_s], RaceData[Driver_Code], A11, RaceData[Is_Pit_Lap],"YES" ) -> 2.6
A12: HAM | B12: =_xlfn.MINIFS(RaceData[Pit_Stop_Duration_s], RaceData[Driver_Code], A12, RaceData[Is_Pit_Lap],"YES" ) -> 2.9
A13: ALO | B13: =_xlfn.MINIFS(RaceData[Pit_Stop_Duration_s], RaceData[Driver_Code], A13, RaceData[Is_Pit_Lap],"YES" ) -> 2.7
A14: LEC | B14: =_xlfn.MINIFS(RaceData[Pit_Stop_Duration_s], RaceData[Driver_Code], A14, RaceData[Is_Pit_Lap],"YES" ) -> 2.6
A15: NOR | B15: =_xlfn.MINIFS(RaceData[Pit_Stop_Duration_s], RaceData[Driver_Code], A15, RaceData[Is_Pit_Lap],"YES" ) -> 3.1
A17: Driver | B17: Avg Lap Time (S) | C17: Fastest Lap (S) | D17: Fastest Lap No. | E17: Slowest Clean Lap (S) | F17: Std Dev | G17: Rank
A18: VER | B18: =AVERAGEIFS(RaceData[Lap_Time_s], RaceData[Driver_Code], A18, RaceData[Is_Pit_Lap], "NO") -> 94.886545 | C18: =_xlfn.MINIFS(RaceData[Lap_Time_s], RaceData[Driver_Code], A18, RaceData[Is_Pit_Lap], "NO") -> 92.878 | D18: {=INDEX(RaceData[Lap], MATCH(C18, IF(RaceData[Driver_Code]=A18, RaceData[Lap_Time_s]), 0))} -> 2 | E18: =_xlfn.MAXIFS(RaceData[Lap_Time_s], RaceData[Driver_Code], A18, RaceData[Is_Pit_Lap], "NO", RaceData[Lap],">"&1) -> 102.221 | F18: {=STDEV(IF((RaceData[Driver_Code]=A18)*(RaceData[Is_Pit_Lap]="NO"), RaceData[Lap_Time_s]))} -> 1.7054416 | G18: =RANK(B18,B$18:B$22,1) -> 1
A19: HAM | B19: =AVERAGEIFS(RaceData[Lap_Time_s], RaceData[Driver_Code], A19, RaceData[Is_Pit_Lap], "NO") -> 96.070527 | C19: =_xlfn.MINIFS(RaceData[Lap_Time_s], RaceData[Driver_Code], A19, RaceData[Is_Pit_Lap], "NO") -> 94.662 | D19: {=INDEX(RaceData[Lap], MATCH(C19, IF(RaceData[Driver_Code]=A19, RaceData[Lap_Time_s]), 0))} -> 45 | E19: =_xlfn.MAXIFS(RaceData[Lap_Time_s], RaceData[Driver_Code], A19, RaceData[Is_Pit_Lap], "NO", RaceData[Lap],">"&1) -> 103.895 | F19: {=STDEV(IF((RaceData[Driver_Code]=A19)*(RaceData[Is_Pit_Lap]="NO"), RaceData[Lap_Time_s]))} -> 1.6831914 | G19: =RANK(B19,B$18:B$22,1) -> 4
A20: ALO | B20: =AVERAGEIFS(RaceData[Lap_Time_s], RaceData[Driver_Code], A20, RaceData[Is_Pit_Lap], "NO") -> 95.929473 | C20: =_xlfn.MINIFS(RaceData[Lap_Time_s], RaceData[Driver_Code], A20, RaceData[Is_Pit_Lap], "NO") -> 93.538 | D20: {=INDEX(RaceData[Lap], MATCH(C20, IF(RaceData[Driver_Code]=A20, RaceData[Lap_Time_s]), 0))} -> 2 | E20: =_xlfn.MAXIFS(RaceData[Lap_Time_s], RaceData[Driver_Code], A20, RaceData[Is_Pit_Lap], "NO", RaceData[Lap],">"&1) -> 103.134 | F20: {=STDEV(IF((RaceData[Driver_Code]=A20)*(RaceData[Is_Pit_Lap]="NO"), RaceData[Lap_Time_s]))} -> 1.7012168 | G20: =RANK(B20,B$18:B$22,1) -> 3
A21: LEC | B21: =AVERAGEIFS(RaceData[Lap_Time_s], RaceData[Driver_Code], A21, RaceData[Is_Pit_Lap], "NO") -> 95.851764 | C21: =_xlfn.MINIFS(RaceData[Lap_Time_s], RaceData[Driver_Code], A21, RaceData[Is_Pit_Lap], "NO") -> 93.732 | D21: {=INDEX(RaceData[Lap], MATCH(C21, IF(RaceData[Driver_Code]=A21, RaceData[Lap_Time_s]), 0))} -> 4 | E21: =_xlfn.MAXIFS(RaceData[Lap_Time_s], RaceData[Driver_Code], A21, RaceData[Is_Pit_Lap], "NO", RaceData[Lap],">"&1) -> 103.213 | F21: {=STDEV(IF((RaceData[Driver_Code]=A21)*(RaceData[Is_Pit_Lap]="NO"), RaceData[Lap_Time_s]))} -> 1.6663851 | G21: =RANK(B21,B$18:B$22,1) -> 2
A22: NOR | B22: =AVERAGEIFS(RaceData[Lap_Time_s], RaceData[Driver_Code], A22, RaceData[Is_Pit_Lap], "NO") -> 96.2626 | C22: =_xlfn.MINIFS(RaceData[Lap_Time_s], RaceData[Driver_Code], A22, RaceData[Is_Pit_Lap], "NO") -> 93.974 | D22: {=INDEX(RaceData[Lap], MATCH(C22, IF(RaceData[Driver_Code]=A22, RaceData[Lap_Time_s]), 0))} -> 26 | E22: =_xlfn.MAXIFS(RaceData[Lap_Time_s], RaceData[Driver_Code], A22, RaceData[Is_Pit_Lap], "NO", RaceData[Lap],">"&1) -> 104.741 | F22: {=STDEV(IF((RaceData[Driver_Code]=A22)*(RaceData[Is_Pit_Lap]="NO"), RaceData[Lap_Time_s]))} -> 1.9385359 | G22: =RANK(B22,B$18:B$22,1) -> 5
A24: Fastest Lap of Race | B24: =MIN(RaceData[Lap_Time_s]) -> 92.878
A25: Set By | B25: =INDEX(RaceData[Driver_Code], MATCH(B24, RaceData[Lap_Time_s], 0)) -> VER
A26: On Lap | B26: =INDEX(RaceData[Lap], MATCH(B24, RaceData[Lap_Time_s], 0)) -> 2
A30: Driver | B30: Soft Avg (S) | C30: Medium Avg (S) | D30: Hard Avg (s)
A31: VER | B31: =AVERAGEIFS(RaceData[Lap_Time_s], RaceData[Driver_Code], A31, RaceData[Tyre_Compound], "Soft", RaceData[Is_Pit_Lap], "NO") -> 94.773765 | C31: =AVERAGEIFS(RaceData[Lap_Time_s], RaceData[Driver_Code], A31, RaceData[Tyre_Compound], "Medium", RaceData[Is_Pit_Lap], "NO") -> 94.565762 | D31: =AVERAGEIFS(RaceData[Lap_Time_s], RaceData[Driver_Code], A31, RaceData[Tyre_Compound], "Hard", RaceData[Is_Pit_Lap], "NO") -> 95.395588
A32: HAM | B32: =IFERROR(AVERAGEIFS(RaceData[Lap_Time_s], RaceData[Driver_Code], A32, RaceData[Tyre_Compound], "Soft", RaceData[Is_Pit_Lap], "NO"), "-") -> - | C32: =AVERAGEIFS(RaceData[Lap_Time_s], RaceData[Driver_Code], A32, RaceData[Tyre_Compound], "Medium", RaceData[Is_Pit_Lap], "NO") -> 95.952647 | D32: =AVERAGEIFS(RaceData[Lap_Time_s], RaceData[Driver_Code], A32, RaceData[Tyre_Compound], "Hard", RaceData[Is_Pit_Lap], "NO") -> 96.261381
A33: ALO | B33: =AVERAGEIFS(RaceData[Lap_Time_s], RaceData[Driver_Code], A33, RaceData[Tyre_Compound], "Soft", RaceData[Is_Pit_Lap], "NO") -> 95.670933 | C33: =AVERAGEIFS(RaceData[Lap_Time_s], RaceData[Driver_Code], A33, RaceData[Tyre_Compound], "Medium", RaceData[Is_Pit_Lap], "NO") -> 95.323867 | D33: =AVERAGEIFS(RaceData[Lap_Time_s], RaceData[Driver_Code], A33, RaceData[Tyre_Compound], "Hard", RaceData[Is_Pit_Lap], "NO") -> 96.44796
A34: LEC | B34: =AVERAGEIFS(RaceData[Lap_Time_s], RaceData[Driver_Code], A34, RaceData[Tyre_Compound], "Soft", RaceData[Is_Pit_Lap], "NO") -> 95.652263 | C34: =AVERAGEIFS(RaceData[Lap_Time_s], RaceData[Driver_Code], A34, RaceData[Tyre_Compound], "Medium", RaceData[Is_Pit_Lap], "NO") -> 95.501882 | D34: =AVERAGEIFS(RaceData[Lap_Time_s], RaceData[Driver_Code], A34, RaceData[Tyre_Compound], "Hard", RaceData[Is_Pit_Lap], "NO") -> 96.364316
A35: NOR | B35: =AVERAGEIFS(RaceData[Lap_Time_s], RaceData[Driver_Code], A35, RaceData[Tyre_Compound], "Soft", RaceData[Is_Pit_Lap], "NO") -> 94.654571 | C35: =AVERAGEIFS(RaceData[Lap_Time_s], RaceData[Driver_Code], A35, RaceData[Tyre_Compound], "Medium", RaceData[Is_Pit_Lap], "NO") -> 96.875958 | D35: =AVERAGEIFS(RaceData[Lap_Time_s], RaceData[Driver_Code], A35, RaceData[Tyre_Compound], "Hard", RaceData[Is_Pit_Lap], "NO") -> 96.720941
A38: Driver | B38: Soft Deg (S/lap) | C38: Medium Deg (S/lap) | D38: Hard Deg (S/lap)
A39: VER | B39: 0.128 | C39: 0.062 | D39: 0.024
A40: HAM | B40: - | C40: 0.064 | D40: 0.03
A41: ALO | B41: 0.258 | C41: 0.052 | D41: 0.036
A42: LEC | B42: 0.11 | C42: 0.056 | D42: 0.019
A43: NOR | B43: 0.096 | C43: 0.016 | D43: 0.031
A55: Driver | B55: Pit Lap | C55: Pit Duration (S) | D55: Compound Before | E55: Compound After
A56: ALO | B56: 16 | C56: 2.7 | D56: Soft | E56: Hard
A57: VER | B57: 18 | C57: 2.6 | D57: Soft | E57: Medium
A58: LEC | B58: 20 | C58: 3 | D58: Soft | E58: Medium
A59: HAM | B59: 22 | C59: 3.1 | D59: Medium | E59: Hard
A60: NOR | B60: 25 | C60: 3.8 | D60: Medium | E60: Soft
...

Sheet Dashboard
B2: 2023 BAHRAIN GRAND PRIX - RACE ANALYSIS DASHBOARD
B3: Sakhir Circuit, Bahrain | 57 Laps | 5 Drivers Analysed
B5: Driver | C5: Team | D5: Fastest Lap (S) | E5: Avg Pace (s) | F5: Std Dev | G5: Pit Stops | H5: Fastest Pit (s) | I5: Tyre Strategy
B6: VER | C6: Red Bull | D6: =Analysis!C18 -> 92.878 | E6: =Analysis!B18 -> 94.886545 | F6: =Analysis!F18 -> 1.7054416 | G6: 2 | H6: =Analysis!B11 -> 2.6 | I6: Soft -> Medium -> Hard
B7: HAM | C7: Mercedes | D7: =Analysis!C19 -> 94.662 | E7: =Analysis!B19 -> 96.070527 | F7: =Analysis!F19 -> 1.6831914 | G7: 2 | H7: =Analysis!B12 -> 2.9 | I7: Medium -> Hard -> Medium
B8: ALO | C8: Aston Martin | D8: =Analysis!C20 -> 93.538 | E8: =Analysis!B20 -> 95.929473 | F8: =Analysis!F20 -> 1.7012168 | G8: 2 | H8: =Analysis!B13 -> 2.7 | I8: Soft -> Hard -> Medium
B9: LEC | C9: Ferrari | D9: =Analysis!C21 -> 93.732 | E9: =Analysis!B21 -> 95.851764 | F9: =Analysis!F21 -> 1.6663851 | G9: 2 | H9: =Analysis!B14 -> 2.6 | I9: Soft -> Medium -> Hard
B10: NOR | C10: McLaren | D10: =Analysis!C22 -> 93.974 | E10: =Analysis!B22 -> 96.2626 | F10: =Analysis!F22 -> 1.9385359 | G10: 2 | H10: =Analysis!B15 -> 3.1 | I10: Medium -> Soft -> Hard

Sheet Helper
A1: VER | D1: ALO | G1: LEC | J1: NOR | M1: SOFT TYRES | P1: Lap | Q1: VER | R1: HAM | S1: ALO | T1: LEC | U1: NOR
A2: Lap_On_Tyre | B2: Lap_Time_s | C2: =SLOPE(B3:B19, A3:A19) -> 0.12823529 | D2: Lap_On_Tyre | E2: Lap_Time_s | F2: =SLOPE(E3:E17, D3:D17) -> 0.25776786 | G2: Lap_On_Tyre | H2: Lap_Time_s | I2: =SLOPE(H3:H21, G3:G21) -> 0.10969123 | J2: Lap_On_Tyre | K2: Lap_Time_s | L2: =SLOPE(K3:K16, J3:J16) -> 0.096259341 | P2: 1 | Q2: 97.846 | R2: 99.305 | S2: 97.816 | T2: 97.482 | U2: 99.749
A3: 1 | B3: 97.846 | D3: 1 | E3: 97.816 | G3: 1 | H3: 97.482 | J3: 1 | K3: 93.974 | P3: 2 | Q3: 92.878 | R3: 94.841 | S3: 93.538 | T3: 94.069 | U3: 95.34
A4: 2 | B4: 92.878 | D4: 2 | E4: 93.538 | G4: 2 | H4: 94.069 | J4: 2 | K4: 94.182 | P4: 3 | Q4: 92.975 | R4: 94.82 | S4: 93.89 | T4: 94.034 | U4: 95.399
A5: 3 | B5: 92.975 | D5: 3 | E5: 93.89 | G5: 3 | H5: 94.034 | J5: 3 | K5: 94.459 | P5: 4 | Q5: 93.181 | R5: 95.077 | S5: 94.179 | T5: 93.732 | U5: 95.222
A6: 4 | B6: 93.181 | D6: 4 | E6: 94.179 | G6: 4 | H6: 93.732 | J6: 4 | K6: 94.271 | P6: 5 | Q6: 93.211 | R6: 95.255 | S6: 93.792 | T6: 93.833 | U6: 95.623
A7: 5 | B7: 93.211 | D7: 5 | E7: 93.792 | G7: 5 | H7: 93.833 | J7: 5 | K7: 94.351 | P7: 6 | Q7: 93.175 | R7: 95.301 | S7: 94.146 | T7: 94.108 | U7: 95.605
A8: 6 | B8: 93.175 | D8: 6 | E8: 94.146 | G8: 6 | H8: 94.108 | J8: 6 | K8: 94.388 | P8: 7 | Q8: 93.512 | R8: 95.269 | S8: 94.28 | T8: 94.189 | U8: 95.431
A9: 7 | B9: 93.512 | D9: 7 | E9: 94.28 | G9: 7 | H9: 94.189 | J9: 7 | K9: 94.623 | P9: 8 | Q9: 93.402 | R9: 95.513 | S9: 94.007 | T9: 94.366 | U9: 95.59
A10: 8 | B10: 93.402 | D10: 8 | E10: 94.007 | G10: 8 | H10: 94.366 | J10: 8 | K10: 94.81 | P10: 9 | Q10: 93.299 | R10: 95.118 | S10: 94.493 | T10: 94.742 | U10: 96.046
A11: 9 | B11: 93.299 | D11: 9 | E11: 94.493 | G11: 9 | H11: 94.742 | J11: 9 | K11: 94.532 | P11: 10 | Q11: 93.337 | R11: 95.635 | S11: 94.495 | T11: 94.7 | U11: 95.808
A12: 10 | B12: 93.337 | D12: 10 | E12: 94.495 | G12: 10 | H12: 94.7 | J12: 10 | K12: 94.873 | P12: 11 | Q12: 93.703 | R12: 95.34 | S12: 94.545 | T12: 94.526 | U12: 95.625
A13: 11 | B13: 93.703 | D13: 11 | E13: 94.545 | G13: 11 | H13: 94.526 | J13: 11 | K13: 95.108 | P13: 12 | Q13: 102.216 | R13: 103.759 | S13: 102.967 | T13: 103.213 | U13: 104.639
A14: 12 | B14: 102.216 | D14: 12 | E14: 102.967 | G14: 12 | H14: 103.213 | J14: 12 | K14: 94.859 | P14: 13 | Q14: 102.221 | R14: 103.895 | S14: 103.134 | T14: 103.176 | U14: 104.741
... A16: 14 | B16: 93.814 | D16: 14 | E16: 94.901 | G16: 14 | H16: 94.811 | J16: 14 | K16: 95.35 | P16: 15 | Q16: 94.288 | R16: 95.468 | S16: 94.881 | T16: 95.216 | U16: 96.222
A17: 15 | B17: 94.288 | D17: 15 | E17: 94.881 | G17: 15 | H17: 95.216 | P17: 16 | Q17: 94.057 | R17: 95.924 | S17: 113.515 | T17: 95.232 | U17: 96.298
A18: 16 | B18: 94.057 | G18: 16 | H18: 95.232 | P18: 17 | Q18: 94.039 | R18: 95.938 | S18: 95.752 | T18: 95.422 | U18: 96.528
A19: 17 | B19: 94.039 | G19: 17 | H19: 95.422 | P19: 18 | Q19: 113.928 | R19: 95.5 | S19: 95.783 | T19: 95.346 | U19: 96.216
G20: 18 | H20: 95.346 | P20: 19 | Q20: 93.827 | R20: 95.651 | S20: 96.005 | T20: 95.196 | U20: 96.585
G21: 19 | H21: 95.196 | P21: 20 | Q21: 94.284 | R21: 96.026 | S21: 96.269 | T21: 116.835 | U21: 96.417
P22: 21 | Q22: 93.98 | R22: 95.817 | S22: 96.413 | T22: 94.878 | U22: 96.55
A23: HARD TYRES | P23: 22 | Q23: 93.962 | R23: 114.747 | S23: 96.294 | T23: 95.146 | U23: 96.239
A24: VER | D24: HAM | G24: ALO | J24: LEC | M24: NOR | P24: 23 | Q24: 94.086 | R24: 95.947 | S24: 95.988 | T24: 95.223 | U24: 96.578
A25: Lap_On_Tyre | B25: Lap_Time_s | C25: =SLOPE(B26:B42,A26:A42) -> 0.023816176 | D25: Lap_On_Tyre | E25: Lap_Time_s | F25: =SLOPE(E26:E46,D26:D46) -> 0.029644156 | G25: Lap_On_Tyre | H25: Lap_Time_s | I25: =SLOPE(H26:H50, G26:G50) -> 0.035951538 | J25: Lap_On_Tyre | K25: Lap_Time_s | L25: =SLOPE(K26:K44, J26:J44) -> 0.018740351 | M25: Lap_On_Tyre | N25: Lap_Time_s | O25: =SLOPE(N26:N42, M26:M42) -> 0.030647059 | P25: 24 | Q25: 94.555 | R25: 96.092 | S25: 96.31 | T25: 95.213 | U25: 96.508
A26: 1 | B26: 94.934 | D26: 1 | E26: 95.947 | G26: 1 | H26: 95.752 | J26: 1 | K26: 96.253 | M26: 1 | N26: 96.564 | P26: 25 | Q26: 94.607 | R26: 96.03 | S26: 96.575 | T26: 95.384 | U26: 116.695
A27: 2 | B27: 94.921 | D27: 2 | E27: 96.092 | G27: 2 | H27: 95.783 | J27: 2 | K27: 95.894 | M27: 2 | N27: 96.443 | P27: 26 | Q27: 94.331 | R27: 95.995 | S27: 96.039 | T27: 95.049 | U27: 93.974
A28: 3 | B28: 95.493 | D28: 3 | E28: 96.03 | G28: 3 | H28: 96.005 | J28: 3 | K28: 96.446 | M28: 3 | N28: 96.493 | P28: 27 | Q28: 94.45 | R28: 95.98 | S28: 96.602 | T28: 95.448 | U28: 94.182
A29: 4 | B29: 95.5 | D29: 4 | E29: 95.995 | G29: 4 | H29: 96.269 | J29: 4 | K29: 96.244 | M29: 4 | N29: 96.768 | P29: 28 | Q29: 94.522 | R29: 96.277 | S29: 96.593 | T29: 95.357 | U29: 94.459
A30: 5 | B30: 95.437 | D30: 5 | E30: 95.98 | G30: 5 | H30: 96.413 | J30: 5 | K30: 96.446 | M30: 5 | N30: 96.488 | P30: 29 | Q30: 94.305 | R30: 95.848 | S30: 96.422 | T30: 95.723 | U30: 94.271
A31: 6 | B31: 95.285 | D31: 6 | E31: 96.277 | G31: 6 | H31: 96.294 | J31: 6 | K31: 96.451 | M31: 6 | N31: 96.7 | P31: 30 | Q31: 94.694 | R31: 96.015 | S31: 96.487 | T31: 95.797 | U31: 94.351
A32: 7 | B32: 95.615 | D32: 7 | E32: 95.848 | G32: 7 | H32: 95.988 | J32: 7 | K32: 96.295 | M32: 7 | N32: 96.532 | P32: 31 | Q32: 94.522 | R32: 96.286 | S32: 96.687 | T32: 95.883 | U32: 94.388
A33: 8 | B33: 95.366 | D33: 8 | E33: 96.015 | G33: 8 | H33: 96.31 | J33: 8 | K33: 96.198 | M33: 8 | N33: 96.866 | P33: 32 | Q33: 94.492 | R33: 96.521 | S33: 96.753 | T33: 95.566 | U33: 94.623
A34: 9 | B34: 95.222 | D34: 9 | E34: 96.286 | G34: 9 | H34: 96.575 | J34: 9 | K34: 96.398 | M34: 9 | N34: 96.629 | P34: 33 | Q34: 94.698 | R34: 96.417 | S34: 96.632 | T34: 95.657 | U34: 94.81
A35: 10 | B35: 95.248 | D35: 10 | E35: 96.521 | G35: 10 | H35: 96.039 | J35: 10 | K35: 96.376 | M35: 10 | N35: 96.54 | P35: 34 | Q35: 95.106 | R35: 96.173 | S35: 96.63 | T35: 95.602 | U35: 94.532
A36: 11 | B36: 95.695 | D36: 11 | E36: 96.417 | G36: 11 | H36: 96.602 | J36: 11 | K36: 96.237 | M36: 11 | N36: 96.876 | P36: 35 | Q36: 95.087 | R36: 96.236 | S36: 96.536 | T36: 95.77 | U36: 94.873
A37: 12 | B37: 95.494 | D37: 12 | E37: 96.173 | G37: 12 | H37: 96.593 | J37: 12 | K37: 96.303 | M37: 12 | N37: 96.854 | P37: 36 | Q37: 94.847 | R37: 96.427 | S37: 96.705 | T37: 95.835 | U37: 95.108
... A42: 17 | B42: 95.386 | D42: 17 | E42: 96.627 | G42: 17 | H42: 96.632 | J42: 17 | K42: 96.493 | M42: 17 | N42: 97.094 | P42: 41 | Q42: 94.934 | R42: 96.451 | S42: 96.712 | T42: 96.446 | U42: 96.564
D43: 18 | E43: 96.362 | G43: 18 | H43: 96.63 | J43: 18 | K43: 96.608 | P43: 42 | Q43: 94.921 | R43: 96.347 | S43: 115.784 | T43: 96.244 | U43: 96.443
D44: 19 | E44: 96.451 | G44: 19 | H44: 96.536 | J44: 19 | K44: 96.501 | P44: 43 | Q44: 95.493 | R44: 96.654 | S44: 95.201 | T44: 96.446 | U44: 96.493
D45: 20 | E45: 96.347 | G45: 20 | H45: 96.705 | P45: 44 | Q45: 95.5 | R45: 115.311 | S45: 95.047 | T45: 96.451 | U45: 96.768
...
